Workbook

Sheet How to use
A1: Boomi MFT MVP: Concept Note Review
A2: Reviewed: Boomi Managed File Transfer MVP, Executive Concept Note, Draft v0.2 (9 September 2026)
A3: Review v1.0 and suggested redraft v0.3 (draft), 20 October 2026
A5: Purpose
A6: Test and evidence catalogue for the four Boomi MFT MVP patterns, with review findings, decisions, dependencies and risks for the concept note.
A8: How to use
A9: 1. Close the decisions on the Decisions sheet first. D-MVP-01 and D-MVP-05 decide which AV tests apply to P1, P2 and P4.
A10: 2. On Test catalogue, set Status for each test and fill Run date, Tester and Evidence link. Mark AV tests Not applicable where AV does not run on that pattern.
A11: 3. Summary and Success criteria update themselves from the Status column. A criterion shows Met only when every linked test is Passed or Not applicable.
A12: 4. Record your response to each review finding on Review findings.
A14: Legend
A15: Yellow cells are for you to fill in. All other cells are reference data or formulas.
... A20: Assumed targets (to confirm under D-MVP-07): five consecutive scheduled runs per pattern; alert within 15 minutes; AV limit about 250 MB (G-15).

Sheet Summary
A1: Pattern | B1: Tests | C1: Passed | D1: Failed | E1: Blocked | F1: Not applicable | G1: Not run | H1: Complete %
A2: P1 External to external | B2: =COUNTIF('Test catalogue'!$B$2:$B$71,A2) -> 15 | C2: =COUNTIFS('Test catalogue'!$B$2:$B$71,$A2,'Test catalogue'!$J$2:$J$71,"Passed") -> 0 | D2: =COUNTIFS('Test catalogue'!$B$2:$B$71,$A2,'Test catalogue'!$J$2:$J$71,"Failed") -> 0 | E2: =COUNTIFS('Test catalogue'!$B$2:$B$71,$A2,'Test catalogue'!$J$2:$J$71,"Blocked") -> 0 | F2: =COUNTIFS('Test catalogue'!$B$2:$B$71,$A2,'Test catalogue'!$J$2:$J$71,"Not applicable") -> 0 | G2: =COUNTIFS('Test catalogue'!$B$2:$B$71,$A2,'Test catalogue'!$J$2:$J$71,"Not run") -> 15 | H2: =IF(B2=0,0,(C2+F2)/B2) -> 0
A3: P2 Internal to internal | B3: =COUNTIF('Test catalogue'!$B$2:$B$71,A3) -> 15 | C3: =COUNTIFS('Test catalogue'!$B$2:$B$71,$A3,'Test catalogue'!$J$2:$J$71,"Passed") -> 0 | D3: =COUNTIFS('Test catalogue'!$B$2:$B$71,$A3,'Test catalogue'!$J$2:$J$71,"Failed") -> 0 | E3: =COUNTIFS('Test catalogue'!$B$2:$B$71,$A3,'Test catalogue'!$J$2:$J$71,"Blocked") -> 0 | F3: =COUNTIFS('Test catalogue'!$B$2:$B$71,$A3,'Test catalogue'!$J$2:$J$71,"Not applicable") -> 0 | G3: =COUNTIFS('Test catalogue'!$B$2:$B$71,$A3,'Test catalogue'!$J$2:$J$71,"Not run") -> 15 | H3: =IF(B3=0,0,(C3+F3)/B3) -> 0
A4: P3 External to internal | B4: =COUNTIF('Test catalogue'!$B$2:$B$71,A4) -> 15 | C4: =COUNTIFS('Test catalogue'!$B$2:$B$71,$A4,'Test catalogue'!$J$2:$J$71,"Passed") -> 0 | D4: =COUNTIFS('Test catalogue'!$B$2:$B$71,$A4,'Test catalogue'!$J$2:$J$71,"Failed") -> 0 | E4: =COUNTIFS('Test catalogue'!$B$2:$B$71,$A4,'Test catalogue'!$J$2:$J$71,"Blocked") -> 0 | F4: =COUNTIFS('Test catalogue'!$B$2:$B$71,$A4,'Test catalogue'!$J$2:$J$71,"Not applicable") -> 0 | G4: =COUNTIFS('Test catalogue'!$B$2:$B$71,$A4,'Test catalogue'!$J$2:$J$71,"Not run") -> 15 | H4: =IF(B4=0,0,(C4+F4)/B4) -> 0
A5: P4 Internal to external | B5: =COUNTIF('Test catalogue'!$B$2:$B$71,A5) -> 15 | C5: =COUNTIFS('Test catalogue'!$B$2:$B$71,$A5,'Test catalogue'!$J$2:$J$71,"Passed") -> 0 | D5: =COUNTIFS('Test catalogue'!$B$2:$B$71,$A5,'Test catalogue'!$J$2:$J$71,"Failed") -> 0 | E5: =COUNTIFS('Test catalogue'!$B$2:$B$71,$A5,'Test catalogue'!$J$2:$J$71,"Blocked") -> 0 | F5: =COUNTIFS('Test catalogue'!$B$2:$B$71,$A5,'Test catalogue'!$J$2:$J$71,"Not applicable") -> 0 | G5: =COUNTIFS('Test catalogue'!$B$2:$B$71,$A5,'Test catalogue'!$J$2:$J$71,"Not run") -> 15 | H5: =IF(B5=0,0,(C5+F5)/B5) -> 0
A6: All (platform) | B6: =COUNTIF('Test catalogue'!$B$2:$B$71,A6) -> 10 | C6: =COUNTIFS('Test catalogue'!$B$2:$B$71,$A6,'Test catalogue'!$J$2:$J$71,"Passed") -> 0 | D6: =COUNTIFS('Test catalogue'!$B$2:$B$71,$A6,'Test catalogue'!$J$2:$J$71,"Failed") -> 0 | E6: =COUNTIFS('Test catalogue'!$B$2:$B$71,$A6,'Test catalogue'!$J$2:$J$71,"Blocked") -> 0 | F6: =COUNTIFS('Test catalogue'!$B$2:$B$71,$A6,'Test catalogue'!$J$2:$J$71,"Not applicable") -> 0 | G6: =COUNTIFS('Test catalogue'!$B$2:$B$71,$A6,'Test catalogue'!$J$2:$J$71,"Not run") -> 10 | H6: =IF(B6=0,0,(C6+F6)/B6) -> 0
A7: Total | B7: =SUM(B2:B6) -> 70 | C7: =SUM(C2:C6) -> 0 | D7: =SUM(D2:D6) -> 0 | E7: =SUM(E2:E6) -> 0 | F7: =SUM(F2:F6) -> 0 | G7: =SUM(G2:G6) -> 70 | H7: =IF(B7=0,0,(C7+F7)/B7) -> 0
A9: Review findings by severity
A10: High | B10: =COUNTIF('Review findings'!$C$2:$C$27,A10) -> 6
A11: Medium | B11: =COUNTIF('Review findings'!$C$2:$C$27,A11) -> 14
A12: Low | B12: =COUNTIF('Review findings'!$C$2:$C$27,A12) -> 6
A13: Success criteria met | B13: =COUNTIF('Success criteria'!$F$2:$F$9,"Met") -> 0

Sheet Test catalogue
A1: Test ID | B1: Pattern | C1: Category | D1: Scenario | E1: Steps | F1: Expected result | G1: Success criteria | H1: Evidence required | I1: Priority | J1: Status | K1: Run date | L1: Tester | M1: Evidence link | N1: Notes
A2: P1-TC-01 | B2: P1 External to external | C2: Positive | D2: Scheduled transfer, single file | E2: Place one test file at source; wait for schedule. | F2: File at target; SHA-256 matches source; audit record complete. | G2: SC-1, SC-5 | H2: Audit record, checksum comparison | I2: Must | J2: Not run
A3: P1-TC-02 | B3: P1 External to external | C3: Positive | D3: API-triggered transfer, single file | E3: Call the trigger API with the agreed client and auth. | F3: File at target; SHA-256 matches; audit record shows API trigger. | G3: SC-1, SC-5 | H3: API response, audit record | I3: Must | J3: Not run
A4: P1-TC-03 | B4: P1 External to external | C4: Positive | D4: Multiple files in one run | E4: Place five files at source; run. | F4: All five delivered; one audit record each. | G4: SC-1, SC-5 | H4: Audit extract | I4: Should | J4: Not run
A5: P1-TC-04 | B5: P1 External to external | C5: Positive | D5: Consecutive scheduled runs | E5: Leave schedule running for five cycles with new files each cycle. | F5: Five successful runs, no manual intervention. | G5: SC-2 | H5: Transfer history screenshot or export | I5: Must | J5: Not run
A6: P1-TC-05 | B6: P1 External to external | C6: Positive | D6: Source handling after transfer | E6: Check source after a successful run. | F6: Source file deleted, archived or kept as per D-MVP-08. | G6: SC-1 | H6: Source listing before and after | I6: Should | J6: Not run
A7: P1-TC-06 | B7: P1 External to external | C7: Negative | D7: Infected file (EICAR test file) | E7: Place EICAR test file at source. | F7: File quarantined, not delivered; alert raised; audit outcome shows quarantine. | G7: SC-3, SC-4 | H7: Alert, audit record, target listing | I7: Must | J7: Not run | N7: Applies only if AV runs on this pattern (D-MVP-01, D-MVP-05).
A8: P1-TC-07 | B8: P1 External to external | C8: Negative | D8: AV service unavailable | E8: Stop or block the AV service, then run. | F8: Transfer held (fail closed); alert raised; nothing delivered unscanned. | G8: SC-3, SC-4 | H8: Alert, audit record | I8: Must | J8: Not run | N8: Applies only if AV runs on this pattern (D-MVP-01, D-MVP-05).
A9: P1-TC-08 | B9: P1 External to external | C9: Negative | D9: Target unavailable or credentials rejected | E9: Block target or rotate target credentials, then run. | F9: Retries per policy, then failure alert; no partial file at target. | G9: SC-3 | H9: Alert, retry log, target listing | I9: Must | J9: Not run
A10: P1-TC-09 | B10: P1 External to external | C10: Negative | D10: Non-arrival | E10: Leave source empty through the expected window. | F10: Non-arrival alert raised within target time. | G10: SC-3 | H10: Alert with timestamp | I10: Must | J10: Not run
A11: P1-TC-10 | B11: P1 External to external | C11: Negative | D11: Zero-byte file | E11: Place a zero-byte file at source. | F11: Handled per agreed rule (reject or transfer) with audit outcome. | G11: SC-5 | H11: Audit record | I11: Should | J11: Not run
A12: P1-TC-11 | B12: P1 External to external | C12: Negative | D12: File name breaks naming rule | E12: Place a file with an invalid name. | F12: Not transferred; alert or audit outcome shows rejection. | G12: SC-3, SC-5 | H12: Audit record | I12: Should | J12: Not run
A13: P1-TC-12 | B13: P1 External to external | C13: Negative | D13: Duplicate file name at target | E13: Send a file whose name already exists at target. | F13: Handled per agreed rule (overwrite, version or reject) with audit. | G13: SC-5 | H13: Target listing, audit record | I13: Should | J13: Not run
A14: P1-TC-13 | B14: P1 External to external | C14: Negative | D14: File above AV size limit (G-15) | E14: Place a file larger than the AV limit (about 250 MB). | F14: Deterministic outcome per D-MVP-05; never delivered unscanned; alert raised. | G14: SC-4 | H14: Alert, audit record | I14: Must | J14: Not run | N14: Applies only if AV runs on this pattern (D-MVP-01, D-MVP-05).
A15: P1-TC-14 | B15: P1 External to external | C15: Positive | D15: Largest permitted file within AV limit | E15: Transfer a file just under the AV limit. | F15: Delivered and scanned; duration recorded for sizing. | G15: SC-1 | H15: Audit record with timings | I15: Should | J15: Not run
A16: P1-TC-15 | B16: P1 External to external | C16: Negative | D16: Interrupted transfer | E16: Drop the network mid-transfer. | F16: Resume or restart; no corrupt or partial file left at target. | G16: SC-1, SC-3 | H16: Target checksum, audit record | I16: Should | J16: Not run
A17: P2-TC-01 | B17: P2 Internal to internal | C17: Positive | D17: Scheduled transfer, single file | E17: Place one test file at source; wait for schedule. | F17: File at target; SHA-256 matches source; audit record complete. | G17: SC-1, SC-5 | H17: Audit record, checksum comparison | I17: Must | J17: Not run
A18: P2-TC-02 | B18: P2 Internal to internal | C18: Positive | D18: API-triggered transfer, single file | E18: Call the trigger API with the agreed client and auth. | F18: File at target; SHA-256 matches; audit record shows API trigger. | G18: SC-1, SC-5 | H18: API response, audit record | I18: Must | J18: Not run
A19: P2-TC-03 | B19: P2 Internal to internal | C19: Positive | D19: Multiple files in one run | E19: Place five files at source; run. | F19: All five delivered; one audit record each. | G19: SC-1, SC-5 | H19: Audit extract | I19: Should | J19: Not run
A20: P2-TC-04 | B20: P2 Internal to internal | C20: Positive | D20: Consecutive scheduled runs | E20: Leave schedule running for five cycles with new files each cycle. | F20: Five successful runs, no manual intervention. | G20: SC-2 | H20: Transfer history screenshot or export | I20: Must | J20: Not run
A21: P2-TC-05 | B21: P2 Internal to internal | C21: Positive | D21: Source handling after transfer | E21: Check source after a successful run. | F21: Source file deleted, archived or kept as per D-MVP-08. | G21: SC-1 | H21: Source listing before and after | I21: Should | J21: Not run
A22: P2-TC-06 | B22: P2 Internal to internal | C22: Negative | D22: Infected file (EICAR test file) | E22: Place EICAR test file at source. | F22: File quarantined, not delivered; alert raised; audit outcome shows quarantine. | G22: SC-3, SC-4 | H22: Alert, audit record, target listing | I22: Must | J22: Not run | N22: Applies only if AV runs on this pattern (D-MVP-01, D-MVP-05).
A23: P2-TC-07 | B23: P2 Internal to internal | C23: Negative | D23: AV service unavailable | E23: Stop or block the AV service, then run. | F23: Transfer held (fail closed); alert raised; nothing delivered unscanned. | G23: SC-3, SC-4 | H23: Alert, audit record | I23: Must | J23: Not run | N23: Applies only if AV runs on this pattern (D-MVP-01, D-MVP-05).
A24: P2-TC-08 | B24: P2 Internal to internal | C24: Negative | D24: Target unavailable or credentials rejected | E24: Block target or rotate target credentials, then run. | F24: Retries per policy, then failure alert; no partial file at target. | G24: SC-3 | H24: Alert, retry log, target listing | I24: Must | J24: Not run
A25: P2-TC-09 | B25: P2 Internal to internal | C25: Negative | D25: Non-arrival | E25: Leave source empty through the expected window. | F25: Non-arrival alert raised within target time. | G25: SC-3 | H25: Alert with timestamp | I25: Must | J25: Not run
A26: P2-TC-10 | B26: P2 Internal to internal | C26: Negative | D26: Zero-byte file | E26: Place a zero-byte file at source. | F26: Handled per agreed rule (reject or transfer) with audit outcome. | G26: SC-5 | H26: Audit record | I26: Should | J26: Not run
A27: P2-TC-11 | B27: P2 Internal to internal | C27: Negative | D27: File name breaks naming rule | E27: Place a file with an invalid name. | F27: Not transferred; alert or audit outcome shows rejection. | G27: SC-3, SC-5 | H27: Audit record | I27: Should | J27: Not run
A28: P2-TC-12 | B28: P2 Internal to internal | C28: Negative | D28: Duplicate file name at target | E28: Send a file whose name already exists at target. | F28: Handled per agreed rule (overwrite, version or reject) with audit. | G28: SC-5 | H28: Target listing, audit record | I28: Should | J28: Not run
A29: P2-TC-13 | B29: P2 Internal to internal | C29: Negative | D29: File above AV size limit (G-15) | E29: Place a file larger than the AV limit (about 250 MB). | F29: Deterministic outcome per D-MVP-05; never delivered unscanned; alert raised. | G29: SC-4 | H29: Alert, audit record | I29: Must | J29: Not run | N29: Applies only if AV runs on this pattern (D-MVP-01, D-MVP-05).
A30: P2-TC-14 | B30: P2 Internal to internal | C30: Positive | D30: Largest permitted file within AV limit | E30: Transfer a file just under the AV limit. | F30: Delivered and scanned; duration recorded for sizing. | G30: SC-1 | H30: Audit record with timings | I30: Should | J30: Not run
A31: P2-TC-15 | B31: P2 Internal to internal | C31: Negative | D31: Interrupted transfer | E31: Drop the network mid-transfer. | F31: Resume or restart; no corrupt or partial file left at target. | G31: SC-1, SC-3 | H31: Target checksum, audit record | I31: Should | J31: Not run
A32: P3-TC-01 | B32: P3 External to internal | C32: Positive | D32: Scheduled transfer, single file | E32: Place one test file at source; wait for schedule. | F32: File at target; SHA-256 matches source; audit record complete. | G32: SC-1, SC-5 | H32: Audit record, checksum comparison | I32: Must | J32: Not run
A33: P3-TC-02 | B33: P3 External to internal | C33: Positive | D33: API-triggered transfer, single file | E33: Call the trigger API with the agreed client and auth. | F33: File at target; SHA-256 matches; audit record shows API trigger. | G33: SC-1, SC-5 | H33: API response, audit record | I33: Must | J33: Not run
A34: P3-TC-03 | B34: P3 External to internal | C34: Positive | D34: Multiple files in one run | E34: Place five files at source; run. | F34: All five delivered; one audit record each. | G34: SC-1, SC-5 | H34: Audit extract | I34: Should | J34: Not run
A35: P3-TC-04 | B35: P3 External to internal | C35: Positive | D35: Consecutive scheduled runs | E35: Leave schedule running for five cycles with new files each cycle. | F35: Five successful runs, no manual intervention. | G35: SC-2 | H35: Transfer history screenshot or export | I35: Must | J35: Not run
A36: P3-TC-05 | B36: P3 External to internal | C36: Positive | D36: Source handling after transfer | E36: Check source after a successful run. | F36: Source file deleted, archived or kept as per D-MVP-08. | G36: SC-1 | H36: Source listing before and after | I36: Should | J36: Not run
A37: P3-TC-06 | B37: P3 External to internal | C37: Negative | D37: Infected file (EICAR test file) | E37: Place EICAR test file at source. | F37: File quarantined, not delivered; alert raised; audit outcome shows quarantine. | G37: SC-3, SC-4 | H37: Alert, audit record, target listing | I37: Must | J37: Not run
A38: P3-TC-07 | B38: P3 External to internal | C38: Negative | D38: AV service unavailable | E38: Stop or block the AV service, then run. | F38: Transfer held (fail closed); alert raised; nothing delivered unscanned. | G38: SC-3, SC-4 | H38: Alert, audit record | I38: Must | J38: Not run
A39: P3-TC-08 | B39: P3 External to internal | C39: Negative | D39: Target unavailable or credentials rejected | E39: Block target or rotate target credentials, then run. | F39: Retries per policy, then failure alert; no partial file at target. | G39: SC-3 | H39: Alert, retry log, target listing | I39: Must | J39: Not run
A40: P3-TC-09 | B40: P3 External to internal | C40: Negative | D40: Non-arrival | E40: Leave source empty through the expected window. | F40: Non-arrival alert raised within target time. | G40: SC-3 | H40: Alert with timestamp | I40: Must | J40: Not run
...

Sheet Success criteria
A1: ID | B1: Criterion | C1: Source in v0.2 | D1: Linked tests | E1: Passed or N/A | F1: Status
A2: SC-1 | B2: Each of the four patterns completes a scheduled and an API-triggered transfer, and the target SHA-256 matches the source. | C2: Original 1 | D2: =COUNTIF('Test catalogue'!$G$2:$G$71,"*"&A2&"*") -> 24 | E2: =COUNTIFS('Test catalogue'!$G$2:$G$71,"*"&A2&"*",'Test catalogue'!$J$2:$J$71,"Passed")+COUNTIFS('Test catalogue'!$G$2:$G$71,"*"&A2&"*",'Test catalogue'!$J$2:$J$71,"Not applicable") -> 0 | F2: =IF(AND(D2>0,E2=D2),"Met","Not yet") -> Not yet
A3: SC-2 | B3: Scheduled transfers run for at least five consecutive cycles per pattern with no manual intervention, and transfer history is visible end to end. | C3: Original 2 | D3: =COUNTIF('Test catalogue'!$G$2:$G$71,"*"&A3&"*") -> 4 | E3: =COUNTIFS('Test catalogue'!$G$2:$G$71,"*"&A3&"*",'Test catalogue'!$J$2:$J$71,"Passed")+COUNTIFS('Test catalogue'!$G$2:$G$71,"*"&A3&"*",'Test catalogue'!$J$2:$J$71,"Not applicable") -> 0 | F3: =IF(AND(D3>0,E3=D3),"Met","Not yet") -> Not yet
A4: SC-3 | B4: Non-arrival, transfer failure, AV detection and AV service failure each raise an alert to the agreed channel within the agreed time (target 15 minutes, D-MVP-07). | C4: Original 3, split | D4: =COUNTIF('Test catalogue'!$G$2:$G$71,"*"&A4&"*") -> 25 | E4: =COUNTIFS('Test catalogue'!$G$2:$G$71,"*"&A4&"*",'Test catalogue'!$J$2:$J$71,"Passed")+COUNTIFS('Test catalogue'!$G$2:$G$71,"*"&A4&"*",'Test catalogue'!$J$2:$J$71,"Not applicable") -> 0 | F4: =IF(AND(D4>0,E4=D4),"Met","Not yet") -> Not yet
A5: SC-4 | B5: An infected, unscannable or oversize file is never delivered to any target. | C5: New | D5: =COUNTIF('Test catalogue'!$G$2:$G$71,"*"&A5&"*") -> 12 | E5: =COUNTIFS('Test catalogue'!$G$2:$G$71,"*"&A5&"*",'Test catalogue'!$J$2:$J$71,"Passed")+COUNTIFS('Test catalogue'!$G$2:$G$71,"*"&A5&"*",'Test catalogue'!$J$2:$J$71,"Not applicable") -> 0 | F5: =IF(AND(D5>0,E5=D5),"Met","Not yet") -> Not yet
A6: SC-5 | B6: Every transfer creates an audit record with source, destination, file name, size, SHA-256, start and end timestamps, outcome and correlation ID. | C6: Original 4 | D6: =COUNTIF('Test catalogue'!$G$2:$G$71,"*"&A6&"*") -> 25 | E6: =COUNTIFS('Test catalogue'!$G$2:$G$71,"*"&A6&"*",'Test catalogue'!$J$2:$J$71,"Passed")+COUNTIFS('Test catalogue'!$G$2:$G$71,"*"&A6&"*",'Test catalogue'!$J$2:$J$71,"Not applicable") -> 0 | F6: =IF(AND(D6>0,E6=D6),"Met","Not yet") -> Not yet
A7: SC-6 | B7: Configuration is promoted from dev to test through the agreed mechanism with no manual re-keying; rollback is demonstrated or the gap is recorded against G-13. | C7: New | D7: =COUNTIF('Test catalogue'!$G$2:$G$71,"*"&A7&"*") -> 2 | E7: =COUNTIFS('Test catalogue'!$G$2:$G$71,"*"&A7&"*",'Test catalogue'!$J$2:$J$71,"Passed")+COUNTIFS('Test catalogue'!$G$2:$G$71,"*"&A7&"*",'Test catalogue'!$J$2:$J$71,"Not applicable") -> 0 | F7: =IF(AND(D7>0,E7=D7),"Met","Not yet") -> Not yet
A8: SC-7 | B8: Security controls are evidenced: TLS 1.2 or higher on every leg, credentials held outside configuration (or the G-14 interim control recorded), least-privilege IAM on S3, encryption at rest. | C8: New | D8: =COUNTIF('Test catalogue'!$G$2:$G$71,"*"&A8&"*") -> 5 | E8: =COUNTIFS('Test catalogue'!$G$2:$G$71,"*"&A8&"*",'Test catalogue'!$J$2:$J$71,"Passed")+COUNTIFS('Test catalogue'!$G$2:$G$71,"*"&A8&"*",'Test catalogue'!$J$2:$J$71,"Not applicable") -> 0 | F8: =IF(AND(D8>0,E8=D8),"Met","Not yet") -> Not yet
A9: SC-8 | B9: The support team can restart a failed transfer, replay a transfer and investigate a quarantined file using the draft runbook, without platform team help. | C9: New | D9: =COUNTIF('Test catalogue'!$G$2:$G$71,"*"&A9&"*") -> 1 | E9: =COUNTIFS('Test catalogue'!$G$2:$G$71,"*"&A9&"*",'Test catalogue'!$J$2:$J$71,"Passed")+COUNTIFS('Test catalogue'!$G$2:$G$71,"*"&A9&"*",'Test catalogue'!$J$2:$J$71,"Not applicable") -> 0 | F9: =IF(AND(D9>0,E9=D9),"Met","Not yet") -> Not yet

Sheet Patterns
A1: ID | B1: Pattern | C1: Source | D1: Target | E1: Route | F1: Boundary | G1: AV | H1: What it proves
A2: P1 | B2: External to external | C2: Pega LZ 1 | D2: Pega LZ 2 | E2: Pega LZ 1 > Boomi MFT Cloud > Pega LZ 2 (or via Local Node if AV must apply, D-MVP-01) | F2: Stays outside the internal estate unless routed through the Local Node | G2: Only if routed through the Local Node (D-MVP-01, D-MVP-05) | H2: SaaS to SaaS brokering without internal storage; partner-to-partner routing
A3: P2 | B3: Internal to internal | C3: S3 bucket 1 | D3: S3 bucket 2 | E3: S3 bucket 1 > Boomi MFT Local Node > S3 bucket 2 | F3: Inside the internal AWS boundary only | G3: Per policy (D-MVP-05) | H3: Internal movement, IAM least privilege, encryption at rest, scheduling
A4: P3 | B4: External to internal | C4: Pega LZ 1 | D4: S3 bucket 1 | E4: Pega LZ 1 > Boomi MFT Cloud > Local Node > AV scan > S3 bucket 1 | F4: Inbound trust boundary crossing | G4: Mandatory before the file lands internally | H4: Inbound boundary crossing, AV before landing, quarantine, firewall rules
A5: P4 | B5: Internal to external | C5: S3 bucket 2 | D5: Pega LZ 2 | E5: S3 bucket 2 > Local Node > Boomi MFT Cloud > Pega LZ 2 | F5: Outbound trust boundary crossing | G5: Per policy for outbound (D-MVP-05) | H5: Outbound egress controls, data classification check, partner delivery

Sheet Review findings
A1: ID | B1: Section | C1: Severity | D1: Finding | E1: Recommendation | F1: Author response | G1: Status
A2: F-01 | B2: Document control | C2: Medium | D2: Still v0.2 dated 9 September 2026. The scope change from the earlier single-feed candidate to four platform patterns is not recorded. | E2: Issue v0.3 dated 20 October 2026 with a one-line change note, and record the scope change as a decision with a named owner. | G2: Open
A3: F-02 | B3: 1. Objective | C3: Low | D3: Objective repeats the proposition and has nothing measurable. | E3: Tie it to the four patterns and both trust-boundary directions, and point to the success criteria. | G3: Open
A4: F-03 | B4: 2. Chosen use case | C4: Low | D4: 'Non-Live/Non-Prod interface' suggests a single named interface, which no longer applies. | E4: Use 'Non-production environment; four platform transfer patterns; no live interface'. | G4: Open
A5: F-04 | B5: 2. Chosen use case | C5: Medium | D5: External landing zone gives no access method, tenant or count. Pattern 1 needs two distinct external locations. | E5: Name Pega LZ 1 and Pega LZ 2, state the access protocol (to confirm, D-MVP-02) and the owner. | G5: Open
A6: F-05 | B6: 2. Chosen use case and 7 | C6: Medium | D6: Internal landing zone is a single 'S3 bucket'. Pattern 2 needs a separate source and target. | E6: Name S3 bucket 1 and S3 bucket 2 (or two prefixes with separate IAM policies, D-MVP-03). | G6: Open
A7: F-06 | B7: Diagram | C7: High | D7: Both Pega boxes are labelled 'Landing Zone 1' and both buckets 'S3 bucket 1', so Patterns 1 and 2 read as transfers into the same place. | E7: Relabel as Pega LZ 1, Pega LZ 2, S3 bucket 1, S3 bucket 2. | G7: Open
A8: F-07 | B8: Diagram | C8: High | D8: Dashed pattern lines run endpoint to endpoint and bypass Boomi. Solid lines only point towards Boomi MFT Cloud, so outbound routes (P1, P4) are not shown. | E8: Show the physical route through Boomi for each pattern, with a legend separating route from pattern. See the corrected diagram. | G8: Open
A9: F-08 | B9: Diagram and 5 | C9: High | D9: The note does not say which runtime runs each pattern. If P1 runs on Boomi MFT Cloud alone, the file never reaches the internally hosted AV and passes through Boomi-hosted infrastructure. | E9: Add decision D-MVP-01 (runtime per pattern and where AV runs). State the data classification position for any cloud-only route. | G9: Open
A10: F-09 | B10: 3. What the MVP will prove | C10: Low | D10: AV appears in both columns; 'Monitoring and alerting failure' does not read; scheduling, API trigger and CI/CD (all in scope) are missing. | E10: Restructure into four themes: secure transfer, operability, repeatable delivery, audit and governance. | G10: Open
A11: F-10 | B11: 4. Scope boundaries | C11: Medium | D11: 'Redesign of the retained downstream job chain' belongs to the earlier single-feed candidate and has no meaning for platform patterns. | E11: Remove it. | G11: Open
A12: F-11 | B12: 4. Scope boundaries | C12: Medium | D12: Out of scope list omits items reviewers will ask about: live data, performance and volume, HA and DR failover, payload encryption (PGP), production go-live. | E12: Add them explicitly, or move any you want tested into scope (D-MVP-10 for PGP). | G12: Open
A13: F-12 | B13: 4. Scope boundaries | C13: Medium | D13: API-triggered transfer is in scope but no caller or authentication is named. | E13: Name the test client (for example a Postman collection against the Boomi API) and its auth method (D-MVP-09). | G13: Open
... A27: F-26 | B27: Header and footer | C27: Low | D27: Classification marking appears twice in the footer and once in the header. | E27: Keep one marking in the header and one in the footer, per your document standard. | G27: Open

Sheet Decisions
A1: ID | B1: Decision required | C1: Owner role | D1: Outcome | E1: Date | F1: Status
A2: D-MVP-01 | B2: Runtime that executes each pattern (Boomi MFT Cloud or Local Node) and where AV scanning happens for each. | C2: Boomi Platform Owner with Security Architect | F2: Open
A3: D-MVP-02 | B3: Pega landing zone access method, accounts and keys, and confirmation that two distinct zones are available. | C3: Pega Landing Zone Owner | F3: Open
A4: D-MVP-03 | B4: Internal S3 layout (two buckets or two prefixes), IAM roles and KMS keys for the Local Node. | C4: AWS Platform Owner | F4: Open
A5: D-MVP-04 | B5: Credential storage for non-production: vault or PAM, or an interim control (G-14). | C5: Security Architect | F5: Open
A6: D-MVP-05 | B6: AV policy per pattern, maximum test file size against the AV limit (G-15, about 250 MB) and the behaviour for oversize files. | C6: Boomi Platform Owner with Security Architect | F6: Open
A7: D-MVP-06 | B7: Configuration promotion mechanism for dev to test and how rollback is evidenced (G-13). | C7: Boomi Platform Owner | F7: Open
A8: D-MVP-07 | B8: Alert channel for the MVP (email or Teams versus ServiceNow) and the alert response target. | C8: Service Management Lead | F8: Open
A9: D-MVP-08 | B9: Post-transfer handling of the source file (delete, archive or keep) and the retention period. | C9: Integration Architect | F9: Open
A10: D-MVP-09 | B10: API trigger client and its authentication method. | C10: Integration Architect | F10: Open
A11: D-MVP-10 | B11: Whether payload encryption (PGP) is in or out of MVP scope. | C11: Security Architect | F11: Open
A12: D-MVP-11 | B12: Sign-off authority for the evidence pack and the forum that receives the adoption recommendation. | C12: Design Authority Chair | F12: Open

Sheet Dependencies
A1: ID | B1: Dependency | C1: Owner role | D1: Due | E1: Status
A2: DEP-01 | B2: Boomi MFT runtimes available in non-production: Boomi MFT Cloud tenant and internally hosted Local Node, with AV (MDE) enabled. | C2: Boomi Platform Owner | E2: Open
A3: DEP-02 | B3: End-to-end connectivity: firewall and allow-list rules for Local Node to Boomi MFT Cloud, and Boomi egress IPs allow-listed on the Pega side. | C3: Infrastructure Lead | E3: Open
A4: DEP-03 | B4: Two Pega landing zones with accounts and keys for Boomi. | C4: Pega Landing Zone Owner | E4: Open
A5: DEP-04 | B5: Two S3 locations with IAM roles and KMS keys granted to the Local Node. | C5: AWS Platform Owner | E5: Open
A6: DEP-05 | B6: Representative or synthetic test files agreed, with file naming rules and data classification confirmed (including whether the data may be held in external SaaS). | C6: Integration Architect with Data Owner | E6: Open
A7: DEP-06 | B7: Credential storage arrangement agreed (D-MVP-04). | C7: Security Architect | E7: Open
A8: DEP-07 | B8: Alert destination set up and reachable (D-MVP-07). | C8: Service Management Lead | E8: Open
A9: DEP-08 | B9: Security approval to connect non-production to external SaaS. | C9: Security Architect | E9: Open

Sheet Risks
A1: ID | B1: Risk | C1: Impact / Likelihood | D1: Mitigation | E1: Owner role
A2: R-MVP-01 | B2: Firewall and allow-list lead times delay P3 and P4. | C2: High / High | D2: Raise change requests at note sign-off; test connectivity first. | E2: Infrastructure Lead
A3: R-MVP-02 | B3: P1 routed through Boomi MFT Cloud bypasses internal AV; files above about 250 MB cannot be scanned (G-15). | C3: High / Medium | D3: Settle D-MVP-01 and D-MVP-05 before build; keep test files under the limit plus one oversize negative test. | E3: Boomi Platform Owner
A4: R-MVP-03 | B4: No native CI/CD for MFT configuration (G-13), so SC-6 may not be met. | C4: Medium / High | D4: Agree the mechanism under D-MVP-06; record the gap if rollback cannot be shown. | E4: Boomi Platform Owner
A5: R-MVP-04 | B5: No native PAM integration (G-14) leads to manual credential handling. | C5: Medium / High | D5: Interim controlled process with audit; record in the evidence pack. | E5: Security Architect
A6: R-MVP-05 | B6: Pega landing zone access (two zones, accounts, keys) arrives late. | C6: Medium / Medium | D6: Confirm D-MVP-02 in week 0; P2 can start without it. | E6: Pega Landing Zone Owner
A7: R-MVP-06 | B7: External SaaS may not accept representative data. | C7: Medium / Medium | D7: Default to synthetic files for P1, P3 and P4. | E7: Integration Architect
A8: R-MVP-07 | B8: ServiceNow and Dynatrace are out of scope, so operational readiness is shown by email or Teams alerts only. | C8: Low / High | D8: State this limit in the recommendation. | E8: Service Management Lead
