Workbook

Sheet README
A1: SDEC consolidated integration requirements
A2: Integration, MFT and events across Create Thread, External User Upload and External User Submission
A3: Version v0.1 (draft), 30 September 2026
A5: How to use
A6: 1 | B6: Start with Journeys for scope, then Requirements. Every requirement row cites the source steps it was derived from.
A7: 2 | B7: Filter Requirements by Category (Integration (API), MFT, Event, Non-functional) or by Target system (NRS, eDMS, HIP, SDEC HCP, Communication Service).
A8: 3 | B8: Yellow cells (Owner, Comments on Requirements; Decision, Date on Open Items) are for you to fill in during review. Priority and Status have drop-down lists.
A9: 4 | B9: Step Trace lists every step from the three source designs with the requirement IDs that cover it. A step with no requirement ID is a user interface or front-end-only step.
A10: 5 | B10: Summary recalculates counts from the Requirements and Open Items sheets.
A12: Sheets
A13: Summary | B13: Counts of requirements by category and status, and open items by journey (formulas).
A14: Journeys | B14: The three journeys: actor, trigger, outcome, systems, HIP involvement and handoff.
A15: Requirements | B15: Consolidated integration, MFT, event and non-functional requirements (INT, MFT, EVT, NFR).
A16: API Catalogue | B16: Every endpoint in the three journeys, with consumer, provider and whether it routes through HIP.
A17: Event Catalogue | B17: Events and asynchronous commands: publisher, subscribers, channel, payload and state change.
A18: Storage and States | B18: Buckets, stores and tables, then the status values each journey sets.
A19: Step Trace | B19: All source steps (J1 Create Thread, J2 External User Document Upload, J3 External User Submission).
A20: Open Items | B20: Questions and decisions from the source notes and from architect review, each with an owner role.
A21: Sources | B21: The draft design pages this workbook consolidates.
A23: Conventions
A24: Journey codes | B24: J1 Create Thread; J2 External User Document Upload; J3 External User Submission (crystallisation). NRS and eDMS are legs inside J3; J1 step 45 reuses the eDMS leg.
A25: Origin | B25: 'Source design' rows restate the draft designs. 'Architect proposal' rows are additions for review and are not yet agreed.
A26: HIP components | B26: API Management, Event Management and File Transfer Manager (MFT with AV Service and S3 landing, quarantine and clean staging buckets), as shown in the NRS integration detail.
A27: Internal user | B27: The thread owner inside the department (shown as the internal user in the source designs).
A28: Companion diagrams | B28: sdec-consolidated-journeys.drawio (journey view) and sdec-consolidated-interaction.drawio (sequence view of all three journeys), each with SVG / PNG copies.

Sheet Summary
A1: Requirements by category and status
A3: Category | B3: Draft | C3: Handoff (outside J1 design scope) | D3: Requirement on NRS | E3: Open | F3: To confirm | G3: Proposed | H3: Total
A4: Integration (API) | B4: =COUNTIFS(Requirements!$B$2:$B$50,$A4,Requirements!$L$2:$L$50,B$3) -> 10 | C4: =COUNTIFS(Requirements!$B$2:$B$50,$A4,Requirements!$L$2:$L$50,C$3) -> 1 | D4: =COUNTIFS(Requirements!$B$2:$B$50,$A4,Requirements!$L$2:$L$50,D$3) -> 2 | E4: =COUNTIFS(Requirements!$B$2:$B$50,$A4,Requirements!$L$2:$L$50,E$3) -> 1 | F4: =COUNTIFS(Requirements!$B$2:$B$50,$A4,Requirements!$L$2:$L$50,F$3) -> 0 | G4: =COUNTIFS(Requirements!$B$2:$B$50,$A4,Requirements!$L$2:$L$50,G$3) -> 0 | H4: =SUM(B4:G4) -> 14
A5: MFT | B5: =COUNTIFS(Requirements!$B$2:$B$50,$A5,Requirements!$L$2:$L$50,B$3) -> 13 | C5: =COUNTIFS(Requirements!$B$2:$B$50,$A5,Requirements!$L$2:$L$50,C$3) -> 0 | D5: =COUNTIFS(Requirements!$B$2:$B$50,$A5,Requirements!$L$2:$L$50,D$3) -> 0 | E5: =COUNTIFS(Requirements!$B$2:$B$50,$A5,Requirements!$L$2:$L$50,E$3) -> 0 | F5: =COUNTIFS(Requirements!$B$2:$B$50,$A5,Requirements!$L$2:$L$50,F$3) -> 1 | G5: =COUNTIFS(Requirements!$B$2:$B$50,$A5,Requirements!$L$2:$L$50,G$3) -> 0 | H5: =SUM(B5:G5) -> 14
A6: Event | B6: =COUNTIFS(Requirements!$B$2:$B$50,$A6,Requirements!$L$2:$L$50,B$3) -> 10 | C6: =COUNTIFS(Requirements!$B$2:$B$50,$A6,Requirements!$L$2:$L$50,C$3) -> 0 | D6: =COUNTIFS(Requirements!$B$2:$B$50,$A6,Requirements!$L$2:$L$50,D$3) -> 0 | E6: =COUNTIFS(Requirements!$B$2:$B$50,$A6,Requirements!$L$2:$L$50,E$3) -> 1 | F6: =COUNTIFS(Requirements!$B$2:$B$50,$A6,Requirements!$L$2:$L$50,F$3) -> 0 | G6: =COUNTIFS(Requirements!$B$2:$B$50,$A6,Requirements!$L$2:$L$50,G$3) -> 2 | H6: =SUM(B6:G6) -> 13
A7: Non-functional | B7: =COUNTIFS(Requirements!$B$2:$B$50,$A7,Requirements!$L$2:$L$50,B$3) -> 0 | C7: =COUNTIFS(Requirements!$B$2:$B$50,$A7,Requirements!$L$2:$L$50,C$3) -> 0 | D7: =COUNTIFS(Requirements!$B$2:$B$50,$A7,Requirements!$L$2:$L$50,D$3) -> 0 | E7: =COUNTIFS(Requirements!$B$2:$B$50,$A7,Requirements!$L$2:$L$50,E$3) -> 0 | F7: =COUNTIFS(Requirements!$B$2:$B$50,$A7,Requirements!$L$2:$L$50,F$3) -> 0 | G7: =COUNTIFS(Requirements!$B$2:$B$50,$A7,Requirements!$L$2:$L$50,G$3) -> 8 | H7: =SUM(B7:G7) -> 8
A8: Total | B8: =SUM(B4:B7) -> 33 | C8: =SUM(C4:C7) -> 1 | D8: =SUM(D4:D7) -> 2 | E8: =SUM(E4:E7) -> 2 | F8: =SUM(F4:F7) -> 1 | G8: =SUM(G4:G7) -> 10 | H8: =SUM(H4:H7) -> 49
A9: Check: total equals number of requirement rows | H9: =IF(H8=COUNTA(Requirements!$A$2:$A$50),"OK","Mismatch") -> OK
A11: Requirements by target system (contains)
A12: Target system | B12: Requirements | C12: Must
A13: NRS | B13: =COUNTIFS(Requirements!$J$2:$J$50,"*NRS*") -> 13 | C13: =COUNTIFS(Requirements!$J$2:$J$50,"*NRS*",Requirements!$K$2:$K$50,"Must") -> 13
A14: eDMS | B14: =COUNTIFS(Requirements!$J$2:$J$50,"*eDMS*") -> 9 | C14: =COUNTIFS(Requirements!$J$2:$J$50,"*eDMS*",Requirements!$K$2:$K$50,"Must") -> 9
A15: HIP | B15: =COUNTIFS(Requirements!$J$2:$J$50,"*HIP*") -> 16 | C15: =COUNTIFS(Requirements!$J$2:$J$50,"*HIP*",Requirements!$K$2:$K$50,"Must") -> 16
A16: SDEC HCP | B16: =COUNTIFS(Requirements!$J$2:$J$50,"*SDEC HCP*") -> 4 | C16: =COUNTIFS(Requirements!$J$2:$J$50,"*SDEC HCP*",Requirements!$K$2:$K$50,"Must") -> 4
A17: SDEC | B17: =COUNTIFS(Requirements!$J$2:$J$50,"SDEC") -> 3 | C17: =COUNTIFS(Requirements!$J$2:$J$50,"SDEC",Requirements!$K$2:$K$50,"Must") -> 3
A18: Communication Service | B18: =COUNTIFS(Requirements!$J$2:$J$50,"*Communication Service*") -> 2 | C18: =COUNTIFS(Requirements!$J$2:$J$50,"*Communication Service*",Requirements!$K$2:$K$50,"Must") -> 1
A19: All | B19: =COUNTIFS(Requirements!$J$2:$J$50,"All") -> 7 | C19: =COUNTIFS(Requirements!$J$2:$J$50,"All",Requirements!$K$2:$K$50,"Must") -> 7
A20: SDEC and All count exact matches; other rows count any row whose target list contains the name.
A23: Open items by journey
A24: Journey | B24: Open | C24: All items
A25: J1 | B25: =COUNTIFS('Open Items'!$B$2:$B$25,$A25,'Open Items'!$G$2:$G$25,"Open") -> 7 | C25: =COUNTIFS('Open Items'!$B$2:$B$25,$A25) -> 8
A26: J2 | B26: =COUNTIFS('Open Items'!$B$2:$B$25,$A26,'Open Items'!$G$2:$G$25,"Open") -> 3 | C26: =COUNTIFS('Open Items'!$B$2:$B$25,$A26) -> 3
A27: J3 | B27: =COUNTIFS('Open Items'!$B$2:$B$25,$A27,'Open Items'!$G$2:$G$25,"Open") -> 9 | C27: =COUNTIFS('Open Items'!$B$2:$B$25,$A27) -> 9
A28: All | B28: =COUNTIFS('Open Items'!$B$2:$B$25,$A28,'Open Items'!$G$2:$G$25,"Open") -> 4 | C28: =COUNTIFS('Open Items'!$B$2:$B$25,$A28) -> 4

Sheet Journeys
A1: Journey | B1: Name | C1: Actor | D1: Trigger | E1: Outcome | F1: Systems | G1: HIP involvement | H1: Handoff | I1: Source
A2: J1 | B2: Create Thread | C2: Internal user (thread owner) | D2: Internal user selects Create Thread in the workspace (already authenticated and authorised to create threads) | E2: Thread in pending status with technical and business reference; attachments passed to eDMS; recipient notified (proposed) | F2: Internal user browser, SDEC front end (internal, MDTP), SDEC Thread Manager (HCP), HIP File Transfer Manager, eDMS (Doxis) | G2: File upload per attachment (separate File Upload sequence, pattern TBC); eDMS transfer at step 45; thread confirmation event (proposed) | H2: Recipient (external user) is asked to provide documents: leads into J2 | I2: J1
A3: J2 | B3: External User Document Upload | C3: External user | D3: External user selects documents to upload against a thread interaction | E3: Documents clean-staged in HIP (or quarantined); session, interaction and document state updated; user notified | F3: External user browser, SDEC front end (external, MDTP), HIP File Transfer Manager with AV Service and S3 landing / quarantine / clean staging buckets, SDEC Thread Manager (HCP) | G3: File Transfer API, pre-signed URL generation, landing bucket, AV scan, quarantine, clean staging, upload outcome events | H3: Clean-staged documents are referenced by the submission: leads into J3 | I3: J2
A4: J3 | B4: External User Submission (crystallisation) | C4: External user; Internal user notified | D4: External user clicks submit on the interaction response | E4: Signed submission with attachments held by NRS (evidential) and ingested by eDMS; both users notified; staged files deleted | F4: SDEC front end (external and internal), SDEC Thread Manager, HIP API Management, Event Management and File Transfer Manager, NRS, eDMS, Communication Service, SMS Gateway | G4: NRS Submission and Attachment APIs via API Management; file transfer request queue; transfers to NRS and eDMS; transfer, acceptance and deletion events | H4: End of journey | I4: J3, NRS

Sheet Requirements
A1: ID | B1: Category | C1: Title | D1: Requirement | E1: Source steps | F1: From | G1: To | H1: Pattern | I1: HIP component | J1: Target system | K1: Priority | L1: Status | M1: Open items | N1: Origin | O1: Owner | P1: Comments
A2: INT-01 | B2: Integration (API) | C2: Create thread API | D2: SDEC front end (internal) shall call the Thread Service API (POST) to create a thread entity record once contact details are captured. Thread Manager shall generate the technical and business-facing thread references together and set the thread to Pending thread created. The business reference is returned only at the confirmation step, not in the create response. | E2: J1 steps 9, 10, 11, 12 | F2: SDEC front end (internal) | G2: SDEC Thread Manager | H2: Sync REST | I2: TBC | J2: SDEC HCP | K2: Must | L2: Draft | M2: OI-01, OI-02, OI-06, OI-19 | N2: Source design
A3: INT-02 | B3: Integration (API) | C3: Submit thread API | D3: SDEC front end (internal) shall submit the confirmed thread to Thread Manager via the Submission Service API (PUT). Thread Manager updates the thread and returns a submission response. | E3: J1 steps 40, 41, 42, 43, 44 | F3: SDEC front end (internal) | G3: SDEC Thread Manager | H3: Sync REST | I3: TBC | J3: SDEC HCP | K3: Must | L3: Draft | M3: OI-05, OI-08, OI-19 | N3: Source design
A4: INT-03 | B4: Integration (API) | C4: Thread attachments to eDMS | D4: On thread submission, Thread Manager shall initiate transfer of the thread's attached files to eDMS, reusing the eDMS ingestion leg of the submission journey (EVT-07, MFT-10, EVT-08). | E4: J1 steps 45; J3 steps 25, 26, 29 | F4: SDEC Thread Manager | G4: eDMS (Doxis) | H4: Async command + REST | I4: Event Management; File Transfer Manager | J4: eDMS | K4: Must | L4: Handoff (outside J1 design scope) | M4: OI-08 | N4: Source design
A5: INT-04 | B5: Integration (API) | C5: File upload request (consumer side) | D5: Front-end Service (external) shall request uploads through the HIP File Transfer API, passing document metadata and thread / interaction ids, and relay the returned pre-signed URLs to the browser. File content never passes through the front end. | E5: J2 steps 5, 7, 10 | F5: SDEC front end (external) | G5: HIP File Transfer Manager | H5: Sync REST | I5: File Transfer Manager (API Management TBC) | J5: HIP | K5: Must | L5: Draft | M5: OI-22 | N5: Source design
A6: INT-05 | B6: Integration (API) | C6: Submission initiation API | D6: Front-end Service (external) shall call Thread Manager POST /interaction/submissions with submission content and signed hash. Thread Manager records Submission requested and returns a synchronous acknowledgement only; NRS and eDMS processing continues asynchronously. | E6: J3 steps 6, 7, 8, 9 | F6: SDEC front end (external) | G6: SDEC Thread Manager | H6: Sync REST (ack only) | I6: TBC | J6: SDEC HCP | K6: Must | L6: Draft | M6: OI-19 | N6: Source design
A7: INT-06 | B7: Integration (API) | C7: Submission content integrity | D7: The browser shall hash the web form content (SHA-256 TBC). Front-end Service (external) validates the hash and signs it if not already signed. The signed hash travels with the payload to NRS. | E7: J3 steps 2, 3, 4, 5, 11 | F7: Browser / SDEC front end (external) | G7: NRS | H7: Payload attribute | I7: API Management | J7: NRS | K7: Must | L7: Draft | M7: OI-14 | N7: Source design
A8: INT-07 | B8: Integration (API) | C8: NRS Submission API via HIP | D8: Thread Manager shall call the NRS Submission API through HIP API Management with the signed interaction payload and attachment metadata / references. NRS persists the payload to transient storage and returns an NRS submission id, which Thread Manager stores. | E8: J3 steps 11, 12, 13, 14; Requirements for NRS 1 | F8: SDEC Thread Manager | G8: NRS | H8: Sync REST | I8: API Management | J8: NRS | K8: Must | L8: Draft | M8: OI-12, OI-13 | N8: Source design
A9: INT-08 | B9: Integration (API) | C9: NRS Attachment API via HIP | D9: Thread Manager shall call the NRS Attachment API through HIP API Management with the NRS submission id and document metadata. NRS generates and returns pre-signed upload URLs to Thread Manager. | E9: J3 steps 15, 16, 17; Requirements for NRS 1 | F9: SDEC Thread Manager | G9: NRS | H9: Sync REST | I9: API Management | J9: NRS | K9: Must | L9: Draft | M9: OI-15 | N9: Source design
A10: INT-09 | B10: Integration (API) | C10: NRS APIs published through iPaaS | D10: NRS shall publish its Submission and Attachment APIs via HIP (iPaaS) API Management. | E10: Requirements for NRS 1 | F10: NRS | G10: HIP API Management | H10: API publication | I10: API Management | J10: NRS | K10: Must | L10: Requirement on NRS | M10: OI-12 | N10: Source design
A11: INT-10 | B11: Integration (API) | C11: NRS capacity for SDEC volumes | D11: NRS shall enhance its APIs, services and underlying infrastructure to support SDEC projected transaction and attachment (document) volumes and attachment sizes. | E11: Requirements for NRS 2 | F11: NRS | G11: NRS | H11: Capacity | I11: API Management; File Transfer Manager | J11: NRS | K11: Must | L11: Requirement on NRS | M11: OI-21, NFR-08 | N11: Source design
A12: INT-11 | B12: Integration (API) | C12: eDMS upload document API | D12: eDMS shall expose an upload document API reachable from HIP File Transfer Manager, accepting documents, document metadata and transaction context, and returning success / failure and eDMS document references. | E12: J3 steps 26, 27, 28 | F12: HIP File Transfer Manager | G12: eDMS (Doxis) | H12: Sync REST | I12: File Transfer Manager | J12: eDMS | K12: Must | L12: Draft | M12: OI-13, OI-18 | N12: Source design
A13: INT-12 | B13: Integration (API) | C13: Notification request | D13: Thread Manager shall call the Communication Service ('Send notification', endpoint TBC) to trigger email / SMS to the external user and email to the internal user through the SMS Gateway. Response status handling is covered by the communication design. | E13: J3 steps 33, 37, 38 | F13: SDEC Thread Manager | G13: Communication Service | H13: Sync REST | I13: TBC | J13: Communication Service | K13: Must | L13: Draft | M13: OI-17 | N13: Source design
... A17: MFT-02 | B17: MFT | C17: Upload strategy and pre-signed URLs | D17: File Transfer Manager shall select single or multi-part upload per file from its size and generate time-limited pre-signed URLs scoped to the landing bucket. | E17: J2 steps 6 | F17: HIP File Transfer Manager | G17: HIP File Transfer Manager | H17: Internal | I17: File Transfer Manager | J17: HIP | K17: Must | L17: Draft | M17: OI-21 | N17: Source design
A18: MFT-03 | B18: MFT | C18: Landing bucket for direct upload | D18: Browsers shall upload directly to a HIP landing bucket (AWS S3) using the pre-signed URLs. | E18: J2 steps 11 | F18: External user browser | G18: HIP landing bucket | H18: File transfer | I18: File Transfer Manager | J18: HIP | K18: Must | L18: Draft | N18: Source design
A19: MFT-04 | B19: MFT | C19: AV scan and validation | D19: File Transfer Manager shall scan and validate every uploaded file through the AV Service before it can be used downstream. | E19: J2 steps 12 | F19: HIP File Transfer Manager | G19: AV Service | H19: Internal | I19: File Transfer Manager | J19: HIP | K19: Must | L19: Draft | M19: OI-21 | N19: Source design
A20: MFT-05 | B20: MFT | C20: Quarantine | D20: Files failing AV or validation shall be moved to a quarantine bucket (AWS S3) and never released downstream. | E20: J2 steps 13 | F20: HIP File Transfer Manager | G20: Quarantine bucket | H20: Internal | I20: File Transfer Manager | J20: HIP | K20: Must | L20: Draft | M20: NFR-07 | N20: Source design
A21: MFT-06 | B21: MFT | C21: Clean staging | D21: Clean, valid files shall be moved to a clean staging bucket (AWS S3), which is the only source for onward transfers to NRS and eDMS. | E21: J2 steps 18; J3 steps 19, 26 | F21: HIP File Transfer Manager | G21: Clean staging bucket | H21: Internal | I21: File Transfer Manager | J21: HIP | K21: Must | L21: Draft | N21: Source design
A22: MFT-07 | B22: MFT | C22: Upload outcome events | D22: File Transfer Manager shall publish file_upload_succeeded or file_upload_failed (with error details) for each file collection, consumed by Front-end Service (external) and Thread Manager. | E22: J2 steps 14, 19 | F22: HIP File Transfer Manager | G22: SDEC front end (external); Thread Manager | H22: Event | I22: Event Management | J22: HIP | K22: Must | L22: Draft | M22: OI-10 | N22: Source design
A23: MFT-08 | B23: MFT | C23: File transfer request queue | D23: File Transfer Manager shall consume asynchronous commands from Thread Manager on a file transfer request queue: transfer to NRS, transfer to eDMS and delete staged files. Each command carries the file collection reference, target identifier(s) and transaction context. | E23: J3 steps 18, 25, 39 | F23: SDEC Thread Manager | G23: HIP File Transfer Manager | H23: Async command | I23: Event Management; File Transfer Manager | J23: HIP | K23: Must | L23: Draft | M23: OI-20 | N23: Source design
A24: MFT-09 | B24: MFT | C24: Transfer to NRS transient storage | D24: File Transfer Manager shall upload clean-staged files to NRS transient storage using the NRS-issued pre-signed URLs supplied in the command. | E24: J3 steps 19, 20 | F24: HIP File Transfer Manager | G24: NRS transient storage | H24: File transfer | I24: File Transfer Manager | J24: NRS | K24: Must | L24: Draft | M24: OI-15 | N24: Source design
A25: MFT-10 | B25: MFT | C25: Transfer to eDMS | D25: File Transfer Manager shall send clean-staged files with document metadata and transaction context to the eDMS upload document API and handle the synchronous success / failure response. | E25: J3 steps 26, 28; J1 steps 45 | F25: HIP File Transfer Manager | G25: eDMS (Doxis) | H25: Sync REST | I25: File Transfer Manager | J25: eDMS | K25: Must | L25: Draft | M25: OI-18 | N25: Source design
A26: MFT-11 | B26: MFT | C26: Transfer outcome events | D26: File Transfer Manager shall publish a transfer outcome event per target (NRS, eDMS) to Thread Manager: file_transfer_succeeded, and a failure outcome whose name and payload are to be agreed. | E26: J3 steps 21, 29 | F26: HIP File Transfer Manager | G26: SDEC Thread Manager | H26: Event | I26: Event Management | J26: NRS; eDMS | K26: Must | L26: Draft | M26: OI-18 | N26: Source design
A27: MFT-12 | B27: MFT | C27: Staged file deletion | D27: File Transfer Manager shall delete staged files for a file collection on a delete_staged_files command and publish file_deletion_succeeded. | E27: J3 steps 39, 40, 41 | F27: SDEC Thread Manager | G27: HIP File Transfer Manager | H27: Async command + event | I27: Event Management; File Transfer Manager | J27: HIP | K27: Must | L27: Draft | M27: OI-23 | N27: Source design
A28: MFT-13 | B28: MFT | C28: File collection correlation | D28: The file collection id issued at upload shall be the MFT correlation key for upload, transfer and deletion across J2 and J3. | E28: J2 steps 7; J3 steps 18, 25, 39, 41 | F28: HIP File Transfer Manager | G28: All consumers | H28: Data contract | I28: File Transfer Manager | J28: HIP | K28: Must | L28: Draft | M28: OI-13 | N28: Source design
A29: MFT-14 | B29: MFT | C29: Internal user file upload (Create Thread) | D29: Files attached by the internal user when creating a thread shall be uploaded through the separate File Upload sequence and stored in S3. Assumed to reuse MFT-01 to MFT-07; to be confirmed. | E29: J1 steps Loop, 23 | F29: Internal user browser | G29: HIP File Transfer Manager | H29: File transfer | I29: File Transfer Manager | J29: HIP | K29: Must | L29: To confirm | M29: OI-04 | N29: Source design
A30: EVT-01 | B30: Event | C30: document_upload_requested | D30: Front-end Service (external) shall publish document_upload_requested after receiving pre-signed URLs. Thread Manager subscribes, updates the thread interaction status and creates SDEC Document records. | E30: J2 steps 8, 9 | F30: SDEC front end (external) | G30: SDEC Thread Manager | H30: Event | I30: Event Management (TBC) | J30: SDEC HCP | K30: Must | L30: Draft | M30: OI-20 | N30: Source design
A31: EVT-02 | B31: Event | C31: file_upload_failed | D31: File Transfer Manager shall publish file_upload_failed with document references and error details. Front-end Service (external) updates session state and notifies the user; Thread Manager records Document upload failed. | E31: J2 steps 14, 15, 16, 17 | F31: HIP File Transfer Manager | G31: SDEC front end (external); Thread Manager | H31: Event | I31: Event Management | J31: SDEC | K31: Must | L31: Draft | M31: OI-10 | N31: Source design
A32: EVT-03 | B32: Event | C32: file_upload_succeeded | D32: File Transfer Manager shall publish file_upload_succeeded with document references. Front-end Service (external) updates session state and notifies the user; Thread Manager records Document upload succeeded. | E32: J2 steps 19, 20, 21, 22 | F32: HIP File Transfer Manager | G32: SDEC front end (external); Thread Manager | H32: Event | I32: Event Management | J32: SDEC | K32: Must | L32: Draft | N32: Source design
A33: EVT-04 | B33: Event | C33: request_file_transfer (target NRS) | D33: Thread Manager shall send an asynchronous Request File Transfer command for NRS with pre-signed URLs, file collection reference, target identifier(s) and transaction context. | E33: J3 steps 18 | F33: SDEC Thread Manager | G33: HIP File Transfer Manager | H33: Async command | I33: Event Management | J33: NRS | K33: Must | L33: Draft | M33: OI-15, OI-20 | N33: Source design
A34: EVT-05 | B34: Event | C34: file_transfer_succeeded (NRS) | D34: Thread Manager shall consume file_transfer_succeeded for the NRS target and record documents transferred to NRS, independent of eDMS status. | E34: J3 steps 21, 22 | F34: HIP File Transfer Manager | G34: SDEC Thread Manager | H34: Event | I34: Event Management | J34: NRS | K34: Must | L34: Draft | M34: OI-18 | N34: Source design
A35: EVT-06 | B35: Event | C35: attachments_accepted (NRS) | D35: NRS shall notify SDEC asynchronously when a submission and its attachments are accepted (attachments_accepted via HIP Event Management). SDEC prefers an event; the NRS team has suggested polling. | E35: J3 steps A.1, A.2, 23, 24; Requirements for NRS 3 | F35: NRS | G35: SDEC Thread Manager | H35: Event | I35: Event Management | J35: NRS | K35: Must | L35: Open | M35: OI-16 | N35: Source design
A36: EVT-07 | B36: Event | C36: request_file_transfer (target eDMS) | D36: Thread Manager shall send an asynchronous Request File Transfer command for eDMS with file collection reference, target identifier(s) and transaction context. | E36: J3 steps 25; J1 steps 45 | F36: SDEC Thread Manager | G36: HIP File Transfer Manager | H36: Async command | I36: Event Management | J36: eDMS | K36: Must | L36: Draft | M36: OI-20 | N36: Source design
A37: EVT-08 | B37: Event | C37: file_transfer_succeeded (eDMS) | D37: Thread Manager shall consume file_transfer_succeeded for eDMS, with eDMS document references, and set Submission Completed (not dependent on NRS). | E37: J3 steps 29, 30 | F37: HIP File Transfer Manager | G37: SDEC Thread Manager | H37: Event | I37: Event Management | J37: eDMS | K37: Must | L37: Draft | M37: OI-18 | N37: Source design
A38: EVT-09 | B38: Event | C38: submission_completed | D38: Thread Manager shall publish submission_completed (interaction status submitted). Front-end Service (external) notifies the external user; Front-end Service (internal) notifies the internal user. | E38: J3 steps 31, 32, 34, 35, 36 | F38: SDEC Thread Manager | G38: SDEC front end (external and internal) | H38: Event | I38: Event Management (TBC) | J38: SDEC | K38: Must | L38: Draft | M38: OI-20 | N38: Source design
A39: EVT-10 | B39: Event | C39: delete_staged_files | D39: Thread Manager shall send delete_staged_files only after both eDMS ingestion (EVT-08) and NRS acceptance (EVT-06) are confirmed. | E39: J3 steps 39 | F39: SDEC Thread Manager | G39: HIP File Transfer Manager | H39: Async command | I39: Event Management | J39: HIP | K39: Must | L39: Draft | M39: OI-23 | N39: Source design
A40: EVT-11 | B40: Event | C40: file_deletion_succeeded | D40: File Transfer Manager shall publish file_deletion_succeeded (file collection id). Thread Manager updates document statuses to staged files deleted. | E40: J3 steps 41, 42 | F40: HIP File Transfer Manager | G40: SDEC Thread Manager | H40: Event | I40: Event Management | J40: HIP | K40: Must | L40: Draft | N40: Source design
A41: EVT-12 | B41: Event | C41: thread_confirmed (proposed) | D41: An event for thread confirmation shall be added that calls the search service in iPaaS, the email service and the internal outlook service, so the recipient is told a thread is awaiting them. | E41: J1 design note (confirmation) | F41: SDEC Thread Manager | G41: Search service; email service; outlook service | H41: Event | I41: Event Management (TBC) | J41: Communication Service | K41: Should | L41: Proposed | M41: OI-09 | N41: Source design
A42: EVT-13 | B42: Event | C42: Failure outcomes for transfer and deletion | D42: Failure outcomes shall be defined for NRS transfer, eDMS transfer and staged file deletion (for example file_transfer_failed, file_deletion_failed), with Thread Manager state handling. | E42: J3 steps 21, 29, 41 | F42: HIP File Transfer Manager | G42: SDEC Thread Manager | H42: Event | I42: Event Management | J42: NRS; eDMS; HIP | K42: Must | L42: Proposed | M42: OI-18 | N42: Architect proposal
A43: NFR-01 | B43: Non-functional | C43: Correlation identifiers | D43: Thread id, interaction id, file collection id, NRS submission id and eDMS document references shall be propagated in every API header and event envelope and logged by HIP. | E43: J2 steps 7; J3 steps 13, 29 | F43: All | G43: All | H43: Cross-cutting | I43: All HIP components | J43: All | K43: Must | L43: Proposed | M43: OI-07, OI-13 | N43: Architect proposal
...

Sheet API Catalogue
A1: ID | B1: Name | C1: Method / endpoint | D1: Consumer | E1: Provider | F1: Journey steps | G1: Via HIP | H1: In integration scope | I1: Notes
A2: API-01 | B2: Thread Service API (create thread) | C2: POST Thread Service API | D2: SDEC front end (internal) | E2: Thread Manager (Thread Service) | F2: J1 9-12 | G2: TBC | H2: TBC | I2: Endpoint to be confirmed for iPaaS and HCP teams
A3: API-02 | B3: Thread Service API (save details) | C3: PUT Thread Service API | D3: Internal user browser | E3: SDEC front end (internal) | F3: J1 7, 21 | G3: No | H3: No (front end) | I3: Cached at front end
A4: API-03 | B4: Interaction API (save details) | C4: PUT Interaction API | D4: Internal user browser | E4: SDEC front end (internal) | F4: J1 33 | G4: No | H4: No (front end) | I4: Check your answers loop
A5: API-04 | B5: Submission Service API | C5: PUT Submission Service API | D5: SDEC front end (internal) | E5: Thread Manager (Submission Service) | F5: J1 40-44 | G5: TBC | H5: TBC | I5: Handoff point to crystallisation
A6: API-05 | B6: Document uploads | C6: POST /document_uploads | D6: External user browser | E6: Front-end Service (external) | F6: J2 3, 10 | G6: No | H6: No (front end) | I6: Returns pre-signed URLs to browser
A7: API-06 | B7: File Transfer API | C7: POST /file_uploads | D7: Front-end Service (external) | E7: HIP File Transfer Manager | F7: J2 5-7 | G7: Yes | H7: Yes | I7: Microservice listed as TBC - iPaaS / MFT
A8: API-07 | B8: Pre-signed upload | C8: S3 PUT (pre-signed URL) | D8: External user browser | E8: HIP landing bucket | F8: J2 11 | G8: Yes | H8: Yes | I8: Single or multi-part
A9: API-08 | B9: AV Service | C9: AV scan | D9: HIP File Transfer Manager | E9: AV Service | F9: J2 12 | G9: Yes | H9: Yes (HIP capability) | I9: AV ceiling G-15
A10: API-09 | B10: Interaction submissions (front end) | C10: POST /interaction/submissions | D10: External user browser | E10: Front-end Service (external) | F10: J3 3, 9 | G10: No | H10: No (front end) | I10: Carries hash
A11: API-10 | B11: Interaction submissions (Thread Manager) | C11: POST /interaction/submissions | D11: Front-end Service (external) | E11: Thread Manager (Interaction and Document Service) | F11: J3 6-8 | G11: TBC | H11: TBC | I11: Synchronous ack only
A12: API-11 | B12: NRS Submission API | C12: Submission API | D12: Thread Manager | E12: NRS Submission service | F12: J3 11-13 | G12: Yes (API Management) | H12: Yes | I12: NRS to publish via iPaaS
... A16: API-15 | B16: Send notification | C16: TBC - 'Send notification' | D16: Thread Manager | E16: Communication Service | F16: J3 33 | G16: TBC | H16: TBC | I16: SMS Gateway sends email / SMS (J3 37-38)

Sheet Event Catalogue
A1: ID | B1: Event / command | C1: Kind | D1: Publisher | E1: Subscribers | F1: Channel | G1: Journey steps | H1: Payload | I1: State change | J1: Notes
A2: EVT-01 | B2: document_upload_requested | C2: Event | D2: Front-end Service (external) | E2: Thread Manager | F2: Event Management (TBC) or SDEC internal | G2: J2 8-9 | H2: Thread / interaction state; document metadata | I2: Interaction: Document upload requested; SDEC Document records created
A3: EVT-02 | B3: file_upload_failed | C3: Event | D3: HIP File Transfer Manager | E3: Front-end Service (external); Thread Manager | F3: Event Management | G3: J2 14-17 | H3: Document references / metadata; error details | I3: Session and interaction: Document upload failed | J3: Internal / support notification TBC
A4: EVT-03 | B4: file_upload_succeeded | C4: Event | D4: HIP File Transfer Manager | E4: Front-end Service (external); Thread Manager | F4: Event Management | G4: J2 19-22 | H4: Document references / metadata | I4: Session and interaction: Document upload succeeded
A5: EVT-04 | B5: request_file_transfer (NRS) | C5: Command | D5: Thread Manager | E5: HIP File Transfer Manager | F5: File transfer request queue | G5: J3 18 | H5: Pre-signed URLs; file collection reference; target identifier(s); transaction context | I5: None (triggers MFT-09)
A6: EVT-05 | B6: file_transfer_succeeded (NRS) | C6: Event | D6: HIP File Transfer Manager | E6: Thread Manager | F6: Event Management | G6: J3 21-22 | H6: Success (failure outcome TBC) | I6: Documents transferred to NRS | J6: Independent of eDMS
A7: EVT-06 | B7: attachments_accepted | C7: Event | D7: NRS | E7: Thread Manager | F7: Event Management | G7: J3 A.1-A.2 | H7: Attachment acceptance status | I7: NRS documents accepted | J7: NRS suggests polling; SDEC prefers event
A8: EVT-07 | B8: request_file_transfer (eDMS) | C8: Command | D8: Thread Manager | E8: HIP File Transfer Manager | F8: File transfer request queue | G8: J3 25; J1 45 | H8: File collection reference; target identifier(s); transaction context | I8: None (triggers MFT-10)
A9: EVT-08 | B9: file_transfer_succeeded (eDMS) | C9: Event | D9: HIP File Transfer Manager | E9: Thread Manager | F9: Event Management | G9: J3 29-30 | H9: Success; eDMS document references (failure outcome TBC) | I9: Submission completed | J9: Not dependent on NRS
A10: EVT-09 | B10: submission_completed | C10: Event | D10: Thread Manager | E10: Front-end Service (external); Front-end Service (internal) | F10: Event Management (TBC) or SDEC internal | G10: J3 31-32 | H10: Interaction status: submitted | I10: None (drives user notifications)
A11: EVT-10 | B11: delete_staged_files | C11: Command | D11: Thread Manager | E11: HIP File Transfer Manager | F11: File Transfer Manager request queue | G11: J3 39 | H11: File collection id | I11: None (triggers MFT-12) | J11: Gated on EVT-06 and EVT-08
A12: EVT-11 | B12: file_deletion_succeeded | C12: Event | D12: HIP File Transfer Manager | E12: Thread Manager | F12: Event Management | G12: J3 41-42 | H12: File collection id | I12: Document: staged files deleted
A13: EVT-12 | B13: thread_confirmed (proposed) | C13: Event | D13: Thread Manager | E13: Search service (iPaaS); email service; outlook service (internal) | F13: Event Management (TBC) | G13: J1 note | H13: TBC | I13: TBC | J13: Replaces confirmation screen
A14: EVT-13 | B14: file_transfer_failed / file_deletion_failed (proposed) | C14: Event | D14: HIP File Transfer Manager | E14: Thread Manager | F14: Event Management | G14: J3 21, 29, 41 | H14: Error details (TBC) | I14: TBC | J14: Not in source design

Sheet Storage and States
A1: Store | B1: Owner | C1: Journey steps | D1: Purpose | E1: Retention
A2: Landing bucket (AWS S3) | B2: HIP File Transfer Manager | C2: J2 11 | D2: Receives browser uploads via pre-signed URLs | E2: Until scanned
A3: Quarantine bucket (AWS S3) | B3: HIP File Transfer Manager | C3: J2 13 | D3: Infected or invalid files | E3: TBC (NFR-07)
A4: Clean staging bucket (AWS S3) | B4: HIP File Transfer Manager | C4: J2 18; J3 19, 26, 40 | D4: Source for NRS and eDMS transfers | E4: Until J3 step 40 deletion
A5: NRS transient storage (AWS S3) | B5: NRS | C5: J3 12, 20 | D5: Submission payload and attachments before signing | E5: NRS owned
A6: NRS evidential storage | B6: NRS | C6: J3 24 | D6: Signed payload and attachments | E6: NRS owned
A7: eDMS document store | B7: eDMS (Doxis) | C7: J3 27; J1 45 | D7: Records of submitted and thread documents | E7: eDMS owned
A8: SDEC_Thread_Interaction | B8: SDEC Thread Manager | C8: J2 9, 17, 22; J3 7 | D8: Thread interaction status | E8: SDEC owned
A9: SDEC_Interaction | B9: SDEC Thread Manager | C9: J3 14, 22, A.2, 30 | D9: Interaction state, NRS submission id (name differs from SDEC_Thread_Interaction) | E9: SDEC owned
A10: SDEC_Document | B10: SDEC Thread Manager | C10: J2 9, 17, 22; J3 7, 22, A.2, 30, 42 | D10: Document records and status | E10: SDEC owned
A11: Session state | B11: SDEC front end (external) | C11: J2 4, 15, 20 | D11: Upload session status | E11: Session
A12: Thread details cache | B12: SDEC front end (internal) | C12: J1 8, 22, 34 | D12: Draft thread details before submission | E12: Session
A13: Thread record | B13: SDEC Thread Manager | C13: J1 9-11, 42 | D13: Thread entity, technical and business references | E13: SDEC owned
A15: Status values set along the journeys
A16: Entity | B16: Status | C16: Journey steps | D16: Set by | E16: Notes
A17: Thread | B17: Pending thread created | C17: J1 11 | D17: Thread Manager | E17: Draft thread becomes pending
A18: Thread | B18: Thread details updated | C18: J1 42 | D18: Thread Manager | E18: State name after submission TBC (OI-08)
A19: Session | B19: Upload in progress / Document upload requested | C19: J2 4 | D19: Front-end Service (external)
A20: Interaction / document | B20: Document upload requested | C20: J2 9 | D20: Thread Manager | E20: SDEC Document records created
A21: Session / interaction / document | B21: Document upload failed | C21: J2 15, 17 | D21: Front end; Thread Manager | E21: Error details kept
A22: Session / interaction / document | B22: Document upload succeeded | C22: J2 20, 22 | D22: Front end; Thread Manager | E22: Document references kept
A23: Interaction / document | B23: Submission requested | C23: J3 7 | D23: Thread Manager | E23: Signed hash stored
A24: Interaction | B24: NRS submission id recorded | C24: J3 14 | D24: Thread Manager
A25: Interaction / document | B25: Documents transferred to NRS | C25: J3 22 | D25: Thread Manager | E25: Independent of eDMS
A26: Interaction / document | B26: NRS documents accepted | C26: J3 A.2 | D26: Thread Manager | E26: Needed for clean-up gate
A27: Interaction / document | B27: Submission completed | C27: J3 30 | D27: Thread Manager | E27: Not dependent on NRS
A28: Document | B28: Staged files deleted | C28: J3 42 | D28: Thread Manager | E28: End state

Sheet Step Trace
A1: Journey | B1: Step | C1: Phase | D1: Description | E1: Source | F1: Target | G1: Type | H1: API / endpoint | I1: Payload | J1: Data persistence | K1: Microservice | L1: HIP component | M1: Requirement IDs
A2: J1 | B2: 1 | C2: Workspace | D2: Internal user selects Create Thread | E2: Internal user | F2: Browser | G2: User action | H2: N/A | I2: None | J2: N/A | K2: N/A | L2: None
A3: J1 | B3: 2 | C3: Workspace | D3: Browser retrieves Contact Detail page | E3: Browser | F3: SDEC front end (internal) | G3: HTTP | H3: Page request | I3: None | J3: N/A | K3: SDEC front end (internal) | L3: None
A4: J1 | B4: 3 | C4: Workspace | D4: Contact Detail page returned | E4: SDEC front end (internal) | F4: Browser | G4: Response to 2 | H4: N/A | I4: Page | J4: N/A | K4: SDEC front end (internal) | L4: None
A5: J1 | B5: 4 | C5: Workspace | D5: Contact Detail page displayed | E5: Browser | F5: Internal user | G5: UI | H5: N/A | I5: Page | J5: N/A | K5: N/A | L5: None
A6: J1 | B6: 5 | C6: Contact details | D6: Internal user enters contact details (first name, last name, email address, mobile number, NINO) | E6: Internal user | F6: Browser | G6: User action | H6: N/A | I6: Contact details | J6: N/A | K6: N/A | L6: None
A7: J1 | B7: 6 | C7: Contact details | D7: Internal user selects Continue | E7: Internal user | F7: Browser | G7: User action | H7: N/A | I7: Contact details | J7: N/A | K7: N/A | L7: None
A8: J1 | B8: 7 | C8: Contact details | D8: Save contact detail request | E8: Browser | F8: SDEC front end (internal) | G8: REST | H8: POST Thread Service API | I8: Contact details | J8: N/A | K8: SDEC front end (internal) | L8: None
A9: J1 | B9: 8 | C9: Contact details | D9: Persist contact details (note: add API calls under steps 8 and 9 aligned with external auth documentation) | E9: SDEC front end (internal) | F9: SDEC front end (internal) | G9: Internal | H9: N/A | I9: Contact details | J9: Thread details (front end) | K9: SDEC front end (internal) | L9: None | M9: NFR-04
A10: J1 | B10: 9 | C10: Contact details | D10: Create thread request: creates thread entity record (thread in collection) | E10: SDEC front end (internal) | F10: Thread Manager | G10: REST | H10: POST Thread Service API | I10: Contact details, thread draft | J10: Thread record | K10: Thread Service | L10: TBC | M10: INT-01, NFR-04
A11: J1 | B11: 10 | C11: Contact details | D11: Generate thread reference, technical and business facing, at the same time | E11: Thread Manager | F11: Thread Manager | G11: Internal | H11: N/A | I11: Thread reference (technical, business) | J11: Thread record | K11: Thread Service | L11: None | M11: INT-01
A12: J1 | B12: 11 | C12: Contact details | D12: Update state: Pending thread created (draft thread moves to pending status) | E12: Thread Manager | F12: Thread Manager | G12: Internal | H12: N/A | I12: Thread state | J12: Thread record | K12: Thread Service | L12: None | M12: INT-01
A13: J1 | B13: 12 | C13: Contact details | D13: Thread created response (thread reference not passed back here; only at confirmation) | E13: Thread Manager | F13: SDEC front end (internal) | G13: Response to 9 | H13: N/A | I13: Thread created ack | J13: N/A | K13: Thread Service | L13: TBC | M13: INT-01
A14: J1 | B14: 15 | C14: Contact details | D14: Send / Request File page returned | E14: SDEC front end (internal) | F14: Browser | G14: Response to 7 | H14: N/A | I14: Page | J14: N/A | K14: SDEC front end (internal) | L14: None
A15: J1 | B15: 16 | C15: Contact details | D15: Send / Request File page displayed | E15: Browser | F15: Internal user | G15: UI | H15: N/A | I15: Page | J15: N/A | K15: N/A | L15: None
A16: J1 | B16: 17 | C16: Send / request file | D16: Internal user enters thread details: message title, message body | E16: Internal user | F16: Browser | G16: User action | H16: N/A | I16: Message title, message body | J16: N/A | K16: N/A | L16: None
A17: J1 | B17: Loop | C17: Send / request file | D17: For each uploaded file: refer to separate File Upload sequence (file stored in S3) | E17: Browser | F17: HIP File Transfer Manager | G17: File transfer | H17: File Upload sequence (TBC) | I17: Document, metadata | J17: S3 (TBC) | K17: TBC | L17: File Transfer Manager | M17: MFT-14
A18: J1 | B18: 20 | C18: Send / request file | D18: Internal user selects Continue | E18: Internal user | F18: Browser | G18: User action | H18: N/A | I18: Thread details | J18: N/A | K18: N/A | L18: None
A19: J1 | B19: 21 | C19: Send / request file | D19: Save thread detail request | E19: Browser | F19: SDEC front end (internal) | G19: REST | H19: PUT Thread Service API | I19: Thread details | J19: N/A | K19: SDEC front end (internal) | L19: None
A20: J1 | B20: 22 | C20: Send / request file | D20: Thread details cached | E20: SDEC front end (internal) | F20: SDEC front end (internal) | G20: Internal | H20: N/A | I20: Thread details | J20: Thread details cache | K20: SDEC front end (internal) | L20: None
A21: J1 | B21: 23 | C21: Send / request file | D21: Track number of files and file size validation | E21: SDEC front end (internal) | F21: SDEC front end (internal) | G21: Internal | H21: N/A | I21: File count, file sizes | J21: Thread details cache | K21: SDEC front end (internal) | L21: None | M21: MFT-14, NFR-06
A22: J1 | B22: 24 | C22: Send / request file | D22: Check Answers page returned | E22: SDEC front end (internal) | F22: Browser | G22: Response to 21 | H22: N/A | I22: Name, email, address, mobile, NINO, message title, message, uploaded files, response deadline | J22: N/A | K22: SDEC front end (internal) | L22: None
A23: J1 | B23: 27 | C23: Send / request file | D23: Check Answers page displayed | E23: Browser | F23: Internal user | G23: UI | H23: N/A | I23: Page | J23: N/A | K23: N/A | L23: None
A24: J1 | B24: 28 | C24: Check your answers (loop until confirmed) | D24: Internal user selects a Change link | E24: Internal user | F24: Browser | G24: User action | H24: N/A | I24: None | J24: N/A | K24: N/A | L24: None
A25: J1 | B25: 29 | C25: Check your answers (loop until confirmed) | D25: Retrieve selected page | E25: Browser | F25: SDEC front end (internal) | G25: HTTP | H25: Page request | I25: None | J25: N/A | K25: SDEC front end (internal) | L25: None
A26: J1 | B26: 30 | C26: Check your answers (loop until confirmed) | D26: Selected page returned | E26: SDEC front end (internal) | F26: Browser | G26: Response to 29 | H26: N/A | I26: Page | J26: N/A | K26: SDEC front end (internal) | L26: None
A27: J1 | B27: 31 | C27: Check your answers (loop until confirmed) | D27: Selected page displayed | E27: Browser | F27: Internal user | G27: UI | H27: N/A | I27: Page | J27: N/A | K27: N/A | L27: None
A28: J1 | B28: 32 | C28: Check your answers (loop until confirmed) | D28: Internal user updates thread details | E28: Internal user | F28: Browser | G28: User action | H28: N/A | I28: Thread details | J28: N/A | K28: N/A | L28: None
A29: J1 | B29: 33 | C29: Check your answers (loop until confirmed) | D29: Save thread detail request | E29: Browser | F29: SDEC front end (internal) | G29: REST | H29: PUT Interaction API | I29: Thread details | J29: N/A | K29: SDEC front end (internal) | L29: None
A30: J1 | B30: 34 | C30: Check your answers (loop until confirmed) | D30: Thread details cached | E30: SDEC front end (internal) | F30: SDEC front end (internal) | G30: Internal | H30: N/A | I30: Thread details | J30: Thread details cache | K30: SDEC front end (internal) | L30: None
A31: J1 | B31: 35 | C31: Check your answers (loop until confirmed) | D31: Thread details saved response | E31: SDEC front end (internal) | F31: Browser | G31: Response to 33 | H31: N/A | I31: Ack | J31: N/A | K31: SDEC front end (internal) | L31: None
A32: J1 | B32: 36 | C32: Check your answers (loop until confirmed) | D32: Check Answers screen displayed | E32: Browser | F32: Internal user | G32: UI | H32: N/A | I32: Page | J32: N/A | K32: N/A | L32: None
A33: J1 | B33: 39 | C33: Submit thread | D33: Internal user selects Confirm and Send | E33: Internal user | F33: Browser | G33: User action | H33: N/A | I33: None | J33: N/A | K33: N/A | L33: None
A34: J1 | B34: 40 | C34: Submit thread | D34: Submit thread request | E34: Browser | F34: SDEC front end (internal) | G34: REST | H34: PUT Submission Service API | I34: Thread details | J34: N/A | K34: SDEC front end (internal) | L34: None | M34: INT-02
A35: J1 | B35: 41 | C35: Submit thread | D35: Submit thread request | E35: SDEC front end (internal) | F35: Thread Manager | G35: REST | H35: PUT Submission Service API | I35: Thread details | J35: N/A | K35: Submission Service | L35: TBC | M35: INT-02
A36: J1 | B36: 42 | C36: Submit thread | D36: Update thread (thread details) | E36: Thread Manager | F36: Thread Manager | G36: Internal | H36: N/A | I36: Thread details | J36: Thread record | K36: Thread Service | L36: None | M36: INT-02
A37: J1 | B37: 43 | C37: Submit thread | D37: Thread submission response | E37: Thread Manager | F37: SDEC front end (internal) | G37: Response to 41 | H37: N/A | I37: Submission response | J37: N/A | K37: Submission Service | L37: TBC | M37: INT-02
A38: J1 | B38: 44 | C38: Submit thread | D38: Thread submission response | E38: SDEC front end (internal) | F38: Browser | G38: Response to 40 | H38: N/A | I38: Submission response | J38: N/A | K38: SDEC front end (internal) | L38: None | M38: INT-02
A39: J1 | B39: 45 | C39: Submit thread | D39: Initiate file transfer to eDMS (handoff; state of thread after step 42 to be defined) | E39: Thread Manager | F39: eDMS (Doxis) | G39: Async (TBC) | H39: TBC | I39: Thread attachments, metadata | J39: eDMS document store | K39: TBC | L39: File Transfer Manager (assumed) | M39: INT-03, MFT-10, EVT-07
A40: J1 | B40: 49 | C40: Submit thread | D40: Confirmation screen displayed (note: may be removed; thread reference shown here) | E40: Browser | F40: Internal user | G40: UI | H40: N/A | I40: Thread reference, recipient name, message title, message, response deadline, attached files | J40: N/A | K40: N/A | L40: None
...

Sheet Open Items
A1: ID | B1: Journey | C1: Item | D1: Source | E1: Owner role | F1: Related | G1: Status | H1: Decision | I1: Date
A2: OI-01 | B2: J1 | C2: Technical versus business-facing thread reference. Note proposes generating both at step 10; the reference is returned only at confirmation (not steps 13-14). | D2: J1 notes | E2: SDEC solution architect | F2: INT-01 | G2: Proposed decision
A3: OI-02 | B3: J1 | C3: Add API calls under steps 8 and 9 and align with external auth documentation; add generic pass and response call. | D3: J1 notes | E3: SDEC MDTP tech lead | F3: INT-01, NFR-04 | G3: Open
A4: OI-03 | B4: J1 | C4: Orphaned threads when the user leaves the page: database-level clean-up microservice or retention policy change. | D4: J1 notes | E4: SDEC HCP tech lead | F4: NFR-07 | G4: Open
A5: OI-04 | B5: J1 | C5: File upload process for Create Thread needs more discussion; separate File Upload sequence not yet provided. Confirm it reuses the J2 pattern. | D5: J1 notes | E5: HIP MFT lead with SDEC solution architect | F5: MFT-14 | G5: Open
A6: OI-05 | B6: J1 | C6: Correct endpoints for the iPaaS team and HCP team (steps 40-41). | D6: J1 notes | E6: HIP integration architect | F6: INT-02 | G6: Open
A7: OI-06 | B7: J1 | C7: When recipient information is stored in HCP: at step 9 or after step 42. | D7: J1 notes | E7: SDEC solution architect | F7: INT-01 | G7: Open
A8: OI-07 | B8: All | C8: Attributes passed between each sequence step (data contract per interaction). | D8: J1 notes | E8: SDEC solution architect with HIP integration architect | F8: NFR-02 | G8: Open
A9: OI-08 | B9: J1 | C9: Thread state after step 42 before the eDMS transfer at step 45. | D9: J1 notes | E9: SDEC HCP tech lead | F9: INT-03 | G9: Open
A10: OI-09 | B10: J1 | C10: Confirmation screen marked for removal; add thread confirmation event that calls search, email and outlook services. | D10: J1 notes | E10: SDEC product owner | F10: EVT-12 | G10: Open
A11: OI-10 | B11: J2 | C11: Internal user or support notification on upload failure. | D11: J2 diagram note | E11: SDEC product owner | F11: EVT-02, MFT-07 | G11: Open
A12: OI-11 | B12: J2 | C12: Steps 1-2 interaction type shown as '?'. Confirm these are browser-local with no integration. | D12: J2 table | E12: SDEC MDTP tech lead | G12: Open
A13: OI-12 | B13: J3 | C13: Is NRS dependent on a successful eDMS transfer? Avoid if possible; requires consistent document ids and browser hash / signing. | D13: J3 diagram note | E13: NRS service owner with SDEC solution architect | F13: INT-07, INT-13 | G13: Open
A14: OI-13 | B14: J3 | C14: Do we need end-to-end document ids, or can the submission id be used? | D14: J3 diagram note | E14: SDEC solution architect | F14: INT-14, MFT-13 | G14: Open
A15: OI-14 | B15: J3 | C15: Hash algorithm (SHA-256 TBC) and where signing happens: browser or Front-end Service (external). | D15: J3 table | E15: Security architect | F15: INT-06 | G15: Open
A16: OI-15 | B16: J3 | C16: Who obtains NRS pre-signed URLs: Thread Manager (suggested), File Transfer Manager, or Submission API returning them at step 13. | D16: J3 table | E16: HIP integration architect with NRS service owner | F16: INT-08, MFT-09 | G16: Open
A17: OI-16 | B17: J3 | C17: NRS acceptance notification: asynchronous event (SDEC preference) or polling (NRS suggestion). | D17: Requirements for NRS | E17: NRS service owner | F17: EVT-06 | G17: Open
A18: OI-17 | B18: J3 | C18: Communication Service endpoint ('Send notification') and response status handling, covered in the communication design. | D18: J3 table and note | E18: Communication Service owner | F18: INT-12 | G18: Open
A19: OI-18 | B19: J3 | C19: Failure paths for NRS and eDMS transfers are described as 'or has failed etc' only. Define failure events, retries and Thread Manager states. | D19: J3 table | E19: HIP integration architect | F19: MFT-11, EVT-13 | G19: Open
A20: OI-19 | B20: All | C20: Do SDEC MDTP to HCP calls (Thread Service, Submission Service, /interaction/submissions) route through HIP API Management or go direct? | D20: Architect review | E20: HIP integration architect | F20: INT-01, INT-02, INT-05 | G20: Open
A21: OI-20 | B21: All | C21: Which events and commands use HIP Event Management versus an SDEC internal channel (for example document_upload_requested, submission_completed). | D21: Architect review | E21: HIP integration architect | F21: EVT-01, EVT-09, MFT-08 | G21: Open
A22: OI-21 | B22: All | C22: Maximum file size and count versus AV scan ceiling (tracked gap G-15, about 250 MB) and multi-part threshold. | D22: Architect review | E22: HIP MFT lead | F22: MFT-02, MFT-04, NFR-06 | G22: Open
A23: OI-22 | B23: J2 | C23: Microservice for steps 5-6 shown as 'TBC - iPaaS / MFT'. Confirm HIP owns the File Transfer API. | D23: J2 table | E23: HIP MFT lead | F23: MFT-01, INT-04 | G23: Open
A24: OI-23 | B24: J3 | C24: Clean-up gate: what happens to staged files if NRS acceptance or eDMS ingestion never completes. | D24: Architect review | E24: HIP MFT lead with SDEC HCP tech lead | F24: EVT-10, MFT-12, NFR-07 | G24: Open
A25: OI-24 | B25: J3 | C25: Source inconsistencies: table names SDEC_Interaction and SDEC_Thread_Interaction both used; step 28 marked 'Response to 25' (should be 26); steps 23-24 only on the diagram. | D25: Architect review | E25: SDEC solution architect | G25: Open

Sheet Sources
A1: Code | B1: Source design | C1: Date | D1: Coverage
A2: J1 | B2: Create Threads - DRAFT: sequence diagram (Draft) Create Thread - V4 | C2: 29 Sep 2026 | D2: Steps 1-49 (gaps in numbering), notes and assumptions
A3: J2 | B3: External User Document Upload - DRAFT: sequence diagram and interaction table | C3: Undated draft | D3: Steps 1-22 incl. error and success branches
A4: J3 | B4: (Draft) E2E Crystallisation flow: sequence diagram and interaction table | C4: 18 Sep 2026 | D4: Steps 1-42 plus A.1, A.2; Requirements for NRS
A5: NRS | B5: (Draft) NRS integration detail: HIP component view of J3 steps 11-24 | C5: 18 Sep 2026 | D5: Shows HIP API Management, Event Management and File Transfer Manager in every NRS interaction
